<?xml version="1.0" encoding="UTF-8"?>
<!-- Generated by org.testng.reporters.JUnitReportReporter -->
<testsuite hostname="Dell-i37-9Z1F2P2-w11x64" failures="1" tests="6"
	name="ReRun_Failed_TCs_usingIRetryAnalyzer.TestScript" time="0.093"
	errors="0" timestamp="2024-01-25T13:42:01 IST" skipped="5">
	<testcase classname="ReRun_Failed_TCs_usingIRetryAnalyzer.TestScript"
		name="testMethod" time="0.012">
		<failure message="expected [google] but found [Google]"
			type="java.lang.AssertionError">
      <![CDATA[java.lang.AssertionError: expected [google] but found [Google]
at org.testng.Assert.fail(Assert.java:99)
at org.testng.Assert.failNotEquals(Assert.java:1037)
at org.testng.Assert.assertEqualsImpl(Assert.java:140)
at org.testng.Assert.assertEquals(Assert.java:122)
at org.testng.Assert.assertEquals(Assert.java:629)
at org.testng.Assert.assertEquals(Assert.java:639)
at ReRun_Failed_TCs_usingIRetryAnalyzer.TestScript.testMethod(TestScript.java:23)
at java.base/jdk.internal.reflect.DirectMethodHandleAccessor.invoke(DirectMethodHandleAccessor.java:103)
at java.base/java.lang.reflect.Method.invoke(Method.java:580)
at org.testng.internal.MethodInvocationHelper.invokeMethod(MethodInvocationHelper.java:133)
at org.testng.internal.TestInvoker.invokeMethod(TestInvoker.java:598)
at org.testng.internal.TestInvoker.retryFailed(TestInvoker.java:213)
at org.testng.internal.MethodRunner.runInSequence(MethodRunner.java:58)
at org.testng.internal.TestInvoker$MethodInvocationAgent.invoke(TestInvoker.java:824)
at org.testng.internal.TestInvoker.invokeTestMethods(TestInvoker.java:146)
at org.testng.internal.TestMethodWorker.invokeTestMethods(TestMethodWorker.java:146)
at org.testng.internal.TestMethodWorker.run(TestMethodWorker.java:128)
at java.base/java.util.ArrayList.forEach(ArrayList.java:1596)
at org.testng.TestRunner.privateRun(TestRunner.java:794)
at org.testng.TestRunner.run(TestRunner.java:596)
at org.testng.SuiteRunner.runTest(SuiteRunner.java:377)
at org.testng.SuiteRunner.runSequentially(SuiteRunner.java:371)
at org.testng.SuiteRunner.privateRun(SuiteRunner.java:332)
at org.testng.SuiteRunner.run(SuiteRunner.java:276)
at org.testng.SuiteRunnerWorker.runSuite(SuiteRunnerWorker.java:53)
at org.testng.SuiteRunnerWorker.run(SuiteRunnerWorker.java:96)
at org.testng.TestNG.runSuitesSequentially(TestNG.java:1212)
at org.testng.TestNG.runSuitesLocally(TestNG.java:1134)
at org.testng.TestNG.runSuites(TestNG.java:1063)
at org.testng.TestNG.run(TestNG.java:1031)
at org.testng.remote.AbstractRemoteTestNG.run(AbstractRemoteTestNG.java:115)
at org.testng.remote.RemoteTestNG.initAndRun(RemoteTestNG.java:251)
at org.testng.remote.RemoteTestNG.main(RemoteTestNG.java:77)
]]>
    </failure>
	</testcase> <!--
	testMethod -->
	<system-out />
	<testcase classname="ReRun_Failed_TCs_usingIRetryAnalyzer.TestScript"
		name="testMethod" time="0.016">
		<skipped />
	</testcase> <!-- testMethod -->
	<system-out />
	<testcase classname="ReRun_Failed_TCs_usingIRetryAnalyzer.TestScript"
		name="testMethod" time="0.015">
		<skipped />
	</testcase> <!-- testMethod -->
	<system-out />
	<testcase classname="ReRun_Failed_TCs_usingIRetryAnalyzer.TestScript"
		name="testMethod" time="0.012">
		<skipped />
	</testcase> <!-- testMethod -->
	<system-out />
	<testcase classname="ReRun_Failed_TCs_usingIRetryAnalyzer.TestScript"
		name="testMethod" time="0.026">
		<skipped />
	</testcase> <!-- testMethod -->
	<system-out />
	<testcase classname="ReRun_Failed_TCs_usingIRetryAnalyzer.TestScript"
		name="testMethod" time="0.012">
		<skipped />
	</testcase> <!-- testMethod -->
	<system-out />
</testsuite> <!--
ReRun_Failed_TCs_usingIRetryAnalyzer.TestScript -->
