<?xml version="1.0" encoding="UTF-8"?>
<!-- Generated by org.testng.reporters.JUnitReportReporter -->
<testsuite hostname="Dell-i37-9Z1F2P2-w11x64" failures="1" tests="5" name="ReRun4_Failed_TCs_using_TestNgFailedXMLfile.S2_ClassB" time="0.122" errors="0" timestamp="2025-06-25T21:06:14 IST" skipped="3">
  <testcase classname="ReRun4_Failed_TCs_using_TestNgFailedXMLfile.S2_ClassB" name="testCase3" time="0.066"/>
  <system-out/>
  <testcase classname="ReRun4_Failed_TCs_using_TestNgFailedXMLfile.S2_ClassB" name="testCase4" time="0.016">
    <failure message="expected [true] but found [false]" type="java.lang.AssertionError">
      <![CDATA[java.lang.AssertionError: expected [true] but found [false]
at org.testng.Assert.fail(Assert.java:99)
at org.testng.Assert.failNotEquals(Assert.java:1037)
at org.testng.Assert.assertTrue(Assert.java:45)
at org.testng.Assert.assertTrue(Assert.java:55)
at ReRun4_Failed_TCs_using_TestNgFailedXMLfile.S2_ClassB.testCase4(S2_ClassB.java:17)
at java.base/jdk.internal.reflect.DirectMethodHandleAccessor.invoke(DirectMethodHandleAccessor.java:103)
at java.base/java.lang.reflect.Method.invoke(Method.java:580)
at org.testng.internal.MethodInvocationHelper.invokeMethod(MethodInvocationHelper.java:133)
at org.testng.internal.TestInvoker.invokeMethod(TestInvoker.java:598)
at org.testng.internal.TestInvoker.retryFailed(TestInvoker.java:213)
at org.testng.internal.MethodRunner.runInSequence(MethodRunner.java:58)
at org.testng.internal.TestInvoker$MethodInvocationAgent.invoke(TestInvoker.java:824)
at org.testng.internal.TestInvoker.invokeTestMethods(TestInvoker.java:146)
at org.testng.internal.TestMethodWorker.invokeTestMethods(TestMethodWorker.java:146)
at org.testng.internal.TestMethodWorker.run(TestMethodWorker.java:128)
at java.base/java.util.ArrayList.forEach(ArrayList.java:1596)
at org.testng.TestRunner.privateRun(TestRunner.java:794)
at org.testng.TestRunner.run(TestRunner.java:596)
at org.testng.SuiteRunner.runTest(SuiteRunner.java:377)
at org.testng.SuiteRunner.runSequentially(SuiteRunner.java:371)
at org.testng.SuiteRunner.privateRun(SuiteRunner.java:332)
at org.testng.SuiteRunner.run(SuiteRunner.java:276)
at org.testng.SuiteRunnerWorker.runSuite(SuiteRunnerWorker.java:53)
at org.testng.SuiteRunnerWorker.run(SuiteRunnerWorker.java:96)
at org.testng.TestNG.runSuitesSequentially(TestNG.java:1212)
at org.testng.TestNG.runSuitesLocally(TestNG.java:1134)
at org.testng.TestNG.runSuites(TestNG.java:1063)
at org.testng.TestNG.run(TestNG.java:1031)
at org.testng.remote.AbstractRemoteTestNG.run(AbstractRemoteTestNG.java:115)
at org.testng.remote.RemoteTestNG.initAndRun(RemoteTestNG.java:293)
at org.testng.remote.RemoteTestNG.main(RemoteTestNG.java:91)
]]>
    </failure>
  </testcase> <!-- testCase4 -->
  <system-out/>
  <testcase classname="ReRun4_Failed_TCs_using_TestNgFailedXMLfile.S2_ClassB" name="testCase4" time="0.003">
    <skipped/>
  </testcase> <!-- testCase4 -->
  <system-out/>
  <testcase classname="ReRun4_Failed_TCs_using_TestNgFailedXMLfile.S2_ClassB" name="testCase4" time="0.011">
    <skipped/>
  </testcase> <!-- testCase4 -->
  <system-out/>
  <testcase classname="ReRun4_Failed_TCs_using_TestNgFailedXMLfile.S2_ClassB" name="testCase4" time="0.026">
    <skipped/>
  </testcase> <!-- testCase4 -->
  <system-out/>
</testsuite> <!-- ReRun4_Failed_TCs_using_TestNgFailedXMLfile.S2_ClassB -->
