<?xml version="1.0" encoding="UTF-8"?>
<testng-results ignored="0" total="1" passed="0" failed="1" skipped="0">
  <reporter-output>
  </reporter-output>
  <suite started-at="2025-03-18T13:58:09 IST" name="Suite" finished-at="2025-03-18T13:58:30 IST" duration-ms="20903">
    <groups>
    </groups>
    <test started-at="2025-03-18T13:58:09 IST" name="Test" finished-at="2025-03-18T13:58:30 IST" duration-ms="20903">
      <class name="TakingScreenshotOnlyForFailedTestCases_UsingTestNG.S3_TestClass">
        <test-method is-config="true" signature="setup()[pri:0, instance:TakingScreenshotOnlyForFailedTestCases_UsingTestNG.S3_TestClass@54c5a2ff]" started-at="2025-03-18T13:58:09 IST" name="setup" finished-at="2025-03-18T13:58:23 IST" duration-ms="14147" status="PASS">
          <reporter-output>
          </reporter-output>
        </test-method> <!-- setup -->
        <test-method signature="test1()[pri:0, instance:TakingScreenshotOnlyForFailedTestCases_UsingTestNG.S3_TestClass@54c5a2ff]" started-at="2025-03-18T13:58:23 IST" name="test1" finished-at="2025-03-18T13:58:24 IST" duration-ms="744" status="FAIL">
          <exception class="java.lang.AssertionError">
            <message>
              <![CDATA[This test is intentionally failing.]]>
            </message>
            <full-stacktrace>
              <![CDATA[java.lang.AssertionError: This test is intentionally failing.
at org.testng.Assert.fail(Assert.java:99)
at TakingScreenshotOnlyForFailedTestCases_UsingTestNG.S3_TestClass.test1(S3_TestClass.java:26)
at java.base/jdk.internal.reflect.DirectMethodHandleAccessor.invoke(DirectMethodHandleAccessor.java:103)
at java.base/java.lang.reflect.Method.invoke(Method.java:580)
at org.testng.internal.MethodInvocationHelper.invokeMethod(MethodInvocationHelper.java:133)
at org.testng.internal.TestInvoker.invokeMethod(TestInvoker.java:598)
at org.testng.internal.TestInvoker.invokeTestMethod(TestInvoker.java:173)
at org.testng.internal.MethodRunner.runInSequence(MethodRunner.java:46)
at org.testng.internal.TestInvoker$MethodInvocationAgent.invoke(TestInvoker.java:824)
at org.testng.internal.TestInvoker.invokeTestMethods(TestInvoker.java:146)
at org.testng.internal.TestMethodWorker.invokeTestMethods(TestMethodWorker.java:146)
at org.testng.internal.TestMethodWorker.run(TestMethodWorker.java:128)
at java.base/java.util.ArrayList.forEach(ArrayList.java:1596)
at org.testng.TestRunner.privateRun(TestRunner.java:794)
at org.testng.TestRunner.run(TestRunner.java:596)
at org.testng.SuiteRunner.runTest(SuiteRunner.java:377)
at org.testng.SuiteRunner.runSequentially(SuiteRunner.java:371)
at org.testng.SuiteRunner.privateRun(SuiteRunner.java:332)
at org.testng.SuiteRunner.run(SuiteRunner.java:276)
at org.testng.SuiteRunnerWorker.runSuite(SuiteRunnerWorker.java:53)
at org.testng.SuiteRunnerWorker.run(SuiteRunnerWorker.java:96)
at org.testng.TestNG.runSuitesSequentially(TestNG.java:1212)
at org.testng.TestNG.runSuitesLocally(TestNG.java:1134)
at org.testng.TestNG.runSuites(TestNG.java:1063)
at org.testng.TestNG.run(TestNG.java:1031)
at org.testng.remote.AbstractRemoteTestNG.run(AbstractRemoteTestNG.java:115)
at org.testng.remote.RemoteTestNG.initAndRun(RemoteTestNG.java:293)
at org.testng.remote.RemoteTestNG.main(RemoteTestNG.java:91)
]]>
            </full-stacktrace>
          </exception> <!-- java.lang.AssertionError -->
          <reporter-output>
          </reporter-output>
        </test-method> <!-- test1 -->
        <test-method is-config="true" signature="tearDown()[pri:0, instance:TakingScreenshotOnlyForFailedTestCases_UsingTestNG.S3_TestClass@54c5a2ff]" started-at="2025-03-18T13:58:24 IST" name="tearDown" finished-at="2025-03-18T13:58:30 IST" duration-ms="5455" status="PASS">
          <reporter-output>
          </reporter-output>
        </test-method> <!-- tearDown -->
      </class> <!-- TakingScreenshotOnlyForFailedTestCases_UsingTestNG.S3_TestClass -->
    </test> <!-- Test -->
  </suite> <!-- Suite -->
</testng-results>
